<mujoco >
    
    <body name="gello_base" euler="1.57 0 0" pos="0 0 0.1" childclass="ur5e">
      <inertial mass="4.0" pos="0 0 0" diaginertia="0.00443333156 0.00443333156 0.0072"/>
      <geom mesh="base" material="urblue" class="visual"/>

      <body name="gello_shoulder_link" pos="0 0 0" >
        <inertial mass="3.7" euler="1.57 0 0" pos="0 0.06 0" diaginertia="0.0102675 0.0102675 0.00666"/>
        <joint name="gello_shoulder_pan_joint" class="size3" axis="0 1 0"/>
        <geom mesh="L1" material="linkgray" class="visual"/>
        <geom class="collision" size="0.05 0.05" pos="0 0 0" euler="1.57 0 0"/>
        <geom class="collision" size="0.03 0.04" pos="0.04 0.09 0" euler="0 1.57 0"/>
        
        <body name="gello_upper_arm_link" pos="-0.02 0 0" >
          <inertial mass="8.393" pos="0.13 0.09 0.21" diaginertia="0.133886 0.133886 0.0151074"/>
          <joint name="gello_shoulder_lift_joint" class="size3" axis="1 0 0" pos="0.13 0.09 0"/>
          <geom mesh="L2" material="jointgray" class="visual"/>
          <geom class="collision" size="0.03 0.2" pos="0.12 0.09 0.21"/>
          
          <body name="gello_forearm_link" pos="0.02 0 0">
            <inertial mass="2.275" pos="0.02 0.09 0.62" diaginertia="0.0311796 0.0311796 0.004095"/>
            <joint name="gello_elbow_joint" class="size3_limited" axis="1 0 0" pos="0 0.09 0.42"/>          
            <geom mesh="L3" material="linkgray" class="visual"/>
            <geom class="collision" size="0.03 0.2" pos="0.015 0.09 0.62"/>
            <geom class="collision" size="0.03 0.04" pos="0.04 0.09 0.42" euler="0 1.57 0"/>
            

            <body name="gello_wrist_1_link" pos="-0.03 0 0" >
              <inertial mass="1.219" pos="0.09 0.09 0.82" diaginertia="0.0025599 0.0025599 0.0021942"/>
              <joint name="gello_wrist_1_joint" class="size1" axis="1 0 0" pos="0 0.09 0.82"/>
              <geom mesh="L4" material="jointgray" class="visual" pos="0 0 0"/>
              <geom class="collision" size="0.025 0.04" pos="0.09 0.09 0.83" euler="0 1.57 0"/>
              

              <body name="gello_wrist_2_link" pos="0 0.02 0">
                <inertial mass="1.219" pos="0.13 0.03 0.82" diaginertia="0.0025599 0.0025599 0.0021942"/>
                <joint name="gello_wrist_2_joint" axis="0 -1 0" pos="0.13 0.04 0.82" class="size1"/>
                <geom mesh="L5" material="jointgray" class="visual"/>
                <geom class="collision" size="0.03 0.04" pos="0.12 0.04 0.82" euler="1.57 0 0"/>
                
                
                <body name="gello_handle_1_link" pos="0.19 0.03 0.82" euler="3.14 0 -1.57">

                  <inertial mass="0.1889" pos="-0.05 0.05 0" diaginertia="0.00025599 0.00025599 0.00021942"/>
                  <joint name="gello_handle_1_joint" class="size1" range="-3.1415 3.1415" pos = "-0.05 -0.05 0"/>

                  <geom material="linkgray" mesh="handle" class="visual" />
                  <geom material="linkgray" mesh="trigger"  class="visual" euler="-1.57 0.3 3.14" />
                  <geom class="eef_collision" pos="-0.06 0.04 0" euler="0 0 0" size="0.08 0.03"/>

                 
                </body>
                
              </body>
            </body>
          </body>
        </body>
      </body>
    </body>

</mujoco>

